# Copyright (C) YEAR THE PACKAGE'S COPYRIGHT HOLDER
# This file is distributed under the same license as the PACKAGE package.
#
# Fawaz Al-Alayn <Fawaz_ksu@yahoo.com>, 2010.
# Munzir Taha (منذر طه) <munzirtaha@gmail.com>, 2010.
msgid ""
msgstr ""
"Project-Id-Version: \n"
"Report-Msgid-Bugs-To: \n"
"POT-Creation-Date: 2009-07-16 15:00-0400\n"
"PO-Revision-Date: 2010-07-14 10:13+0300\n"
"Last-Translator: Fawaz Alalyan <fawaz_ksu@yahoo.com>\n"
"Language-Team: Arabic <trans-ar@lists.fedoraproject.org>\n"
"MIME-Version: 1.0\n"
"Content-Type: text/plain; charset=UTF-8\n"
"Content-Transfer-Encoding: 8bit\n"
"X-Generator: Lokalize 1.1\n"
"Plural-Forms: nplurals=6; plural=n==0 ? 0 : n==1 ? 1 : n==2 ? 2 : n%100>=3 "
"&& n%100<=10 ? 3 : n%100>=11 && n%100<=99 ? 4 : 5;\n"

#: ../src/handler.py:209
msgid "Dump Written"
msgstr "تمت كتابة التفريغ"

#: ../src/handler.py:210
msgid ""
"The error file has been successfully written to the disk.  The program will "
"now exit."
msgstr "تم كتابة الملف الخاطئ في القرص. وسيقوم البرنامج بالخروج الآن."

#: ../src/handler.py:215
msgid "Dump Not Written"
msgstr "لم تتم كتابة التفريغ"

#: ../src/handler.py:216
msgid "There was a problem writing the error report."
msgstr "كانت هناك مشكلة في كتابة تقرير عن الخطأ."

#: ../src/handler.py:219
msgid "No Network Available"
msgstr "لا توجد شبكة متوفرة"

#: ../src/handler.py:220
msgid ""
"Cannot save a bug report since there is no active network device available."
msgstr "يتعذر حفظ تقرير الخطأ بسبب عدم توفر أجهرة شبكة فعالة."

#: ../src/savers.py:34
#, python-format
msgid ""
"Your bug could not be filed due to the following error when communicating "
"with bugzilla:\n"
"\n"
"%s"
msgstr ""
"مشكلتك لا يمكن تسجيلها بسبب الخطأ التالي عند الاتصال "
"مع bugzilla:\n"
"\n"
"%s"

#: ../src/savers.py:37
#, python-format
msgid ""
"Your bug could not be filed due to bad information in the bug fields.  This "
"is most likely an error in the bug filing program:\n"
"\n"
"%s"
msgstr ""
"مشكلتك لا يمكن تسجيلها بسبب المعلومات غير المناسبة في حقول المشكلة. هذا "
"في الأغلب خطأ في برنامج تسجيل المشكلة:\n"
"\n"
"%s"

#: ../src/savers.py:41
msgid "Unable To File Bug"
msgstr "غير قادر على تسجيل المشكلة"

#: ../src/savers.py:47
msgid "Bug Filing Not Supported"
msgstr "تسجيل المشكلة غير مدعوم"

#: ../src/savers.py:48
msgid ""
"Your distribution does not provide a supported bug filing system, so you "
"cannot save your exception this way."
msgstr ""
"توزيعتك لا يوفر دعم نظام تسجيل المشكلة، لذلك لا يمكنك"
"حفظ خطئك بهذه الطريقة."

#: ../src/savers.py:54
msgid "Invalid Bug Information"
msgstr "معلومات المشكلة غير صالحة"

#: ../src/savers.py:55
msgid "Please provide a valid username, password, and short bug description."
msgstr "الرجاء التزويد باسم مستخدم صالح، كلمة مرور, ووصف قصير للمشكلة."

#: ../src/savers.py:62
msgid "Unable To Login"
msgstr "غير قادر على تسجيل الدخول"

#: ../src/savers.py:63
#, python-format
msgid ""
"There was an error logging into %s using the provided username and password."
msgstr ""
"هنالك مشكلة في الدخول إلى %s باستخدام اسم المستخدم وكلمة المرور المعطاة."

#. Tell the user we created a new bug for them and that they should
#. go add a descriptive comment.
#: ../src/savers.py:99
msgid "Bug Created"
msgstr "تم إنشاء المشكلة"

#: ../src/savers.py:100
#, python-format
msgid ""
"A new bug has been created with your traceback attached. Please add "
"additional information such as what you were doing when you encountered the "
"bug, screenshots, and whatever else is appropriate to the following bug:\n"
"\n"
"%s/%s"
msgstr ""
"مشكلة جديدة أنشئت مع اتصال traceback الخاص بك. الرجاء إضافة"
"معلومات إضافية مثل ماذا كنت تفعل عندما واجهت"
"المشكلة، صور من الشاشة, و أي شيء آخر هو مناسب للمشكلة التالية:\n"
"\n"
"%s/%s"

#. Tell the user which bug they've been CC'd on and that they should
#. go add a descriptive comment.
#: ../src/savers.py:114
msgid "Bug Updated"
msgstr "تم تحديث المشكلة"

#: ../src/savers.py:115
#, python-format
msgid ""
"A bug with your information already exists.  Your account has been added to "
"the CC list and your traceback added as a comment.  Please add additional "
"descriptive information to the following bug:\n"
"\n"
"%s/%s"
msgstr ""
"مشكلة مع معلوماتك موجودة مسبقا. حسابك أضيف إلى"
"قائمة الـ CC و الـ traceback الخاص بك أضيف كملاحظة. الرجاء إضافة معلومات"
"وصفية إضافية إلى المشكلة التالية:\n"
"\n"
"%s/%s"

#. Set the buttons.
#: ../src/ui/gui.py:85
msgid "_Debug"
msgstr "_تصحيح الأخطاء"

#: ../src/ui/gui.py:87 ../src/ui/gui.py:152
msgid "_Exit"
msgstr "_خروج"

#: ../src/ui/gui.py:92
msgid ""
"An unhandled exception has occurred.  This is most likely a bug.  Please "
"save a copy of the detailed exception and file a bug report."
msgstr ""
"حدث خطأ لا يمكن التعامل معه. هذه في الأغلب مشكلة. الرجاء "
"احفظ نسخة من الخطأ المفصل وسجل تقرير المشكلة."

#: tmp/detailed-dialog.glade.h:1
msgid "Info"
msgstr "معلومات"

#: tmp/detailed-dialog.glade.h:2
msgid "_Details"
msgstr "_تفاصيل"

#: tmp/exnSave.glade.h:1
msgid "Bug _description"
msgstr "ت_فاصيل المشكلة"

#: tmp/exnSave.glade.h:2
msgid "Destination _file"
msgstr "_ملف الوجهة"

#: tmp/exnSave.glade.h:3
msgid ""
"Local storage\n"
"Bugzilla\n"
"Remote server (scp)"
msgstr ""
"التخزين المحلي\n"
"Bugzilla\n"
"الخادم البعيد (scp)"

#: tmp/exnSave.glade.h:6
msgid "Please choose a destination for saving your traceback."
msgstr "الرجاء اختيار وجهة لحفظ الـ traceback الخاص بك."

#: tmp/exnSave.glade.h:7
msgid "Save"
msgstr "حفظ"

#: tmp/exnSave.glade.h:8
msgid "Select A File"
msgstr "اختر ملف"

#: tmp/exnSave.glade.h:9
msgid "_Host (host:port)"
msgstr "ال_مضيف (المضيف:المنفذ)"

#: tmp/exnSave.glade.h:10
msgid "_Password"
msgstr "_كلمة المرور"

#: tmp/exnSave.glade.h:11
msgid "_User name"
msgstr "ا_سم المستخدم"


