# Translation of python-meh.master
# Copyright (C) 2009 Fedora Community
# This file is distributed under the same license as the python-meh package.
# Zoltan Hoppar <hopparz@gmail.com>, 2009.
# Nagy István Zoltán <nagyesta@gmail.com>, 2009.
#
msgid ""
msgstr ""
"Project-Id-Version: Python-meh master\n"
"Report-Msgid-Bugs-To: \n"
"POT-Creation-Date: 2009-07-16 15:00-0400\n"
"PO-Revision-Date: 2009-09-15 17:40+0100\n"
"Last-Translator: Nagy István Zoltán <nagyesta@gmail.com>\n"
"Language-Team: Hungarian <fedora-trans-hu@redhat.com>\n"
"MIME-Version: 1.0\n"
"Content-Type: text/plain; charset=utf-8\n"
"Content-Transfer-Encoding: 8bit\n"
"Plural-Forms: nplurals=2; plural=(n!=1);\n"

#: ../src/handler.py:209
msgid "Dump Written"
msgstr "Memóriakép kiírva"

#: ../src/handler.py:210
msgid "The error file has been successfully written to the disk.  The program will now exit."
msgstr "A hiba fájl sikeresen mentésre került a lemezen. A program most kilép."

#: ../src/handler.py:215
msgid "Dump Not Written"
msgstr "Memóriakép nincs kiírva"

#: ../src/handler.py:216
msgid "There was a problem writing the error report."
msgstr "Hiba történt a jelentés rögzítése közben."

#: ../src/handler.py:219
msgid "No Network Available"
msgstr "Nincs elérhető hálózat."

#: ../src/handler.py:220
msgid "Cannot save a bug report since there is no active network device available."
msgstr "Nem tudja a  hibajelentést menteni, mert nincs aktív elérhető hálózati eszköz"

#: ../src/savers.py:34
#, python-format
msgid ""
"Your bug could not be filed due to the following error when communicating with bugzilla:\n"
"\n"
"%s"
msgstr ""
"Az Önnél jelentkezett hibát nem sikerült jelenteni a bugzillával folytatott kommunikációban fellépett hiba miatt:\n"
"\n"
"%s"

#: ../src/savers.py:37
#, python-format
msgid ""
"Your bug could not be filed due to bad information in the bug fields.  This is most likely an error in the bug filing program:\n"
"\n"
"%s"
msgstr ""
"Az Önnél jelentkezett hibát nem sikerült jelenteni, mert a hiba mezőkben nem megfelelő információ van. Ez valószínűleg a hibajelentő program hibája:\n"
"\n"
"%s"

#: ../src/savers.py:41
msgid "Unable To File Bug"
msgstr "A hibajelentés nem lehetséges"

#: ../src/savers.py:47
msgid "Bug Filing Not Supported"
msgstr "A hibajelentés nem támogatott"

#: ../src/savers.py:48
msgid "Your distribution does not provide a supported bug filing system, so you cannot save your exception this way."
msgstr "A disztribúciója nem rendelkezik támogatott hibajelentő rendszerrel, így a kivételt nem mentheti ezen a módon."

#: ../src/savers.py:54
msgid "Invalid Bug Information"
msgstr "Helytelen hibainformáció"

#: ../src/savers.py:55
msgid "Please provide a valid username, password, and short bug description."
msgstr "Kérem adjon egy érvényes felhasználói nevet, jelszavat, és egy rövid hibaleírást."

#: ../src/savers.py:62
msgid "Unable To Login"
msgstr "Bejelentkezés sikertelen"

#: ../src/savers.py:63
#, python-format
msgid "There was an error logging into %s using the provided username and password."
msgstr "A megadott felhasználói névvel és jelszóval nem sikerült bejelentkezni ide: %s."

#. Tell the user we created a new bug for them and that they should
#. go add a descriptive comment.
#: ../src/savers.py:99
msgid "Bug Created"
msgstr "Hiba elkészült"

#: ../src/savers.py:100
#, python-format
msgid ""
"A new bug has been created with your traceback attached. Please add additional information such as what you were doing when you encountered the bug, screenshots, and whatever else is appropriate to the following bug:\n"
"\n"
"%s/%s"
msgstr ""
"Új hiba készült az Ön nyomkövetési információival. Kérem adjon meg további információt, mint például mit csinált a hiba jelentkezésekor, képernyőképek, és bármi, ami ehhez a hibához illő:\n"
"\n"
"%s/%s"

#. Tell the user which bug they've been CC'd on and that they should
#. go add a descriptive comment.
#: ../src/savers.py:114
msgid "Bug Updated"
msgstr "Hiba frissítve"

#: ../src/savers.py:115
#, python-format
msgid ""
"A bug with your information already exists.  Your account has been added to the CC list and your traceback added as a comment.  Please add additional descriptive information to the following bug:\n"
"\n"
"%s/%s"
msgstr ""
"A hiba az Ön információival már létezett.  A fiókja hozzá lett adva a másolat listához és a nyomkövetési információi megjegyzésként.  Kérem adjon meg további leíró információkat a következő hibáról:\n"
"\n"
"%s/%s"

#. Set the buttons.
#: ../src/ui/gui.py:85
msgid "_Debug"
msgstr "_Hibakeresés"

#: ../src/ui/gui.py:87
#: ../src/ui/gui.py:152
msgid "_Exit"
msgstr "_Kilépés"

#: ../src/ui/gui.py:92
msgid "An unhandled exception has occurred.  This is most likely a bug.  Please save a copy of the detailed exception and file a bug report."
msgstr "Egy nem kezelt kivétel történt. Ez valószínűleg egy hiba. Kérem mentsen egy részletes másolatot a kivételről és töltsön ki egy hibajelentést."

#: tmp/detailed-dialog.glade.h:1
msgid "Info"
msgstr "Info"

#: tmp/detailed-dialog.glade.h:2
msgid "_Details"
msgstr "_Részletek"

#: tmp/exnSave.glade.h:1
msgid "Bug _description"
msgstr "Hiba _leírás"

#: tmp/exnSave.glade.h:2
msgid "Destination _file"
msgstr "Cél _fájl"

#: tmp/exnSave.glade.h:3
msgid ""
"Local storage\n"
"Bugzilla\n"
"Remote server (scp)"
msgstr ""
"Helyi tároló\n"
"Bugzilla\n"
"Távoli kiszolgáló (scp)"

#: tmp/exnSave.glade.h:6
msgid "Please choose a destination for saving your traceback."
msgstr "Kérem válasszon a nyomkövetéseihez egy mentési helyet."

#: tmp/exnSave.glade.h:7
msgid "Save"
msgstr "Mentés"

#: tmp/exnSave.glade.h:8
msgid "Select A File"
msgstr "Válasszon egy fájlt"

#: tmp/exnSave.glade.h:9
msgid "_Host (host:port)"
msgstr "_Gépnév (host:port)"

#: tmp/exnSave.glade.h:10
msgid "_Password"
msgstr "_Jelszó"

#: tmp/exnSave.glade.h:11
msgid "_User name"
msgstr "_Felhasználói név"

