# puthon-meh
# Copyright (C) YEAR THE PACKAGE'S COPYRIGHT HOLDER
# This file is distributed under the same license as the PACKAGE package.
# FIRST AUTHOR <EMAIL@ADDRESS>, YEAR.
# Translation to Dutch
# Geert Warrink <geert.warrink@onsnet.nu>, 2009.
#
msgid ""
msgstr ""
"Project-Id-Version: python-meh\n"
"Report-Msgid-Bugs-To: \n"
"POT-Creation-Date: 2009-07-16 15:00-0400\n"
"PO-Revision-Date: 2009-08-27 21:46+0200\n"
"Last-Translator: Geert Warrink <geert.warrink@onsnet.nu>\n"
"Language-Team: nl <nl@li.org>\n"
"MIME-Version: 1.0\n"
"Content-Type: text/plain; charset=UTF-8\n"
"Content-Transfer-Encoding:  \n"

#: ../src/handler.py:209
msgid "Dump Written"
msgstr "Dump geschreven"

#: ../src/handler.py:210
msgid ""
"The error file has been successfully written to the disk.  The program will "
"now exit."
msgstr ""
"Het fout bestand is succesvol naar schijf geschreven.  Het programma wordt "
"nu afgesloten."

#: ../src/handler.py:215
msgid "Dump Not Written"
msgstr "Dump niet geschreven"

#: ../src/handler.py:216
msgid "There was a problem writing the error report."
msgstr "Er was een probleem met het schrijven van het fout rapport."

#: ../src/handler.py:219
msgid "No Network Available"
msgstr "Geen netwerk beschikbaar"

#: ../src/handler.py:220
msgid ""
"Cannot save a bug report since there is no active network device available."
msgstr ""
"Kan geen fout rapport schrijven omdat er geen actief netwerk interface "
"beschikbaar is."

#: ../src/savers.py:34
#, python-format
msgid ""
"Your bug could not be filed due to the following error when communicating "
"with bugzilla:\n"
"\n"
"%s"
msgstr ""
"Jouw fout kon niet opgeslagen worden door de volgende fout tijdens de "
"communicatie met bugzilla:\n"
"\n"
"%s"

#: ../src/savers.py:37
#, python-format
msgid ""
"Your bug could not be filed due to bad information in the bug fields.  This "
"is most likely an error in the bug filing program:\n"
"\n"
"%s"
msgstr ""
"Jouw fout kon niet opgeslagen worden door verkeerde informatie in de fout "
"velden.  Dit is waarschijnlijk een fout in het fout rapporterings "
"programma:\n"
"\n"
"%s"

#: ../src/savers.py:41
msgid "Unable To File Bug"
msgstr "Niet in staat de fout op te slaan"

#: ../src/savers.py:47
msgid "Bug Filing Not Supported"
msgstr "Opslaan van fouten wordt niet ondersteund"

#: ../src/savers.py:48
msgid ""
"Your distribution does not provide a supported bug filing system, so you "
"cannot save your exception this way."
msgstr ""
"Jouw distributie biedt geen ondersteund fout rapporterings systeem, dus je "
"kunt jouw uitzondering niet op deze manier opslaan."

#: ../src/savers.py:54
msgid "Invalid Bug Information"
msgstr "Ongeldige fout informatie"

#: ../src/savers.py:55
msgid "Please provide a valid username, password, and short bug description."
msgstr ""
"Geef a.u.b. een geldige gebruikers naam, wachtwoord, en een korte fout "
"beschrijving op."

#: ../src/savers.py:62
msgid "Unable To Login"
msgstr "Niet in staat om in te loggen"

#: ../src/savers.py:63
#, python-format
msgid ""
"There was an error logging into %s using the provided username and password."
msgstr ""
"Er trad een fout op met het inloggen op %s met de opgegeven gebruikers naam "
"en wachtwoord."

#. Tell the user we created a new bug for them and that they should
#. go add a descriptive comment.
#: ../src/savers.py:99
msgid "Bug Created"
msgstr "Fout aangemaakt"

#: ../src/savers.py:100
#, python-format
msgid ""
"A new bug has been created with your traceback attached. Please add "
"additional information such as what you were doing when you encountered the "
"bug, screenshots, and whatever else is appropriate to the following bug:\n"
"\n"
"%s/%s"
msgstr ""
"Een nieuwe fout is aangemaakt met jouw traceback toegevoegd. Voeg a.u.b. "
"extra informatie toe, zoals wat je aan het doen was toen de fout optrad, "
"schermafdrukken, en wat nog meer van belang kan zijn voor de volgende fout:\n"
"\n"
"%s/%s"

#. Tell the user which bug they've been CC'd on and that they should
#. go add a descriptive comment.
#: ../src/savers.py:114
msgid "Bug Updated"
msgstr "Fout vernieuwd"

#: ../src/savers.py:115
#, python-format
msgid ""
"A bug with your information already exists.  Your account has been added to "
"the CC list and your traceback added as a comment.  Please add additional "
"descriptive information to the following bug:\n"
"\n"
"%s/%s"
msgstr ""
"Een fout met jouw informatie bestaat al.  Jouw account is toegevoegd aan de "
"CC lijst en je traceback is toegevoegd als commentaar.  Voeg a.u.b. extra "
"beschrijvende informatie toe aan de volgende fout:\n"
"\n"
"%s/%s"

#. Set the buttons.
#: ../src/ui/gui.py:85
msgid "_Debug"
msgstr "_Debug"

#: ../src/ui/gui.py:87 ../src/ui/gui.py:152
msgid "_Exit"
msgstr "V_erlaten"

#: ../src/ui/gui.py:92
msgid ""
"An unhandled exception has occurred.  This is most likely a bug.  Please "
"save a copy of the detailed exception and file a bug report."
msgstr ""
"Een niet afgehandelde uitzondering is opgetreden.  Dit is hoogst "
"waarschijnlijk een fout.  Sla a.u.b een kopie van de gedetaileerde "
"uitzondering op en maak een fout rapport aan."

#: tmp/detailed-dialog.glade.h:1
msgid "Info"
msgstr "Info"

#: tmp/detailed-dialog.glade.h:2
msgid "_Details"
msgstr "_Details"

#: tmp/exnSave.glade.h:1
msgid "Bug _description"
msgstr "Fout_beschrijving"

#: tmp/exnSave.glade.h:2
msgid "Destination _file"
msgstr "Bestemmings bestand"

#: tmp/exnSave.glade.h:3
msgid ""
"Local storage\n"
"Bugzilla\n"
"Remote server (scp)"
msgstr ""
"Locale opslag\n"
"Bugzilla\n"
"Server op afstand (scp)"

#: tmp/exnSave.glade.h:6
msgid "Please choose a destination for saving your traceback."
msgstr "Kies a.u.b. een bestemming voor het opslaan van jouw traceback."

#: tmp/exnSave.glade.h:7
msgid "Save"
msgstr "Opslaan"

#: tmp/exnSave.glade.h:8
msgid "Select A File"
msgstr "Selecteer een bestand"

#: tmp/exnSave.glade.h:9
msgid "_Host (host:port)"
msgstr "_Host (host:poort)"

#: tmp/exnSave.glade.h:10
msgid "_Password"
msgstr "_Wachtwoord"

#: tmp/exnSave.glade.h:11
msgid "_User name"
msgstr "_Gebruikers naam"
