# Brazilian Portuguese translation of python-meh.
# This file is distributed under the same license as the python-meh package.
#
# Igor Pires Soares <igor@projetofedora.org>, 2009.
#

msgid ""
msgstr ""
"Project-Id-Version: python-meh\n"
"Report-Msgid-Bugs-To: https://bugzilla.redhat.com/\n"
"POT-Creation-Date: 2009-07-16 15:00-0400\n"
"PO-Revision-Date: 2009-08-26 19:51-0300\n"
"Last-Translator: Igor Pires Soares <igor@projetofedora.org>\n"
"Language-Team: Brazilian Portuguese <fedora-trans-pt_br@redhat.com>\n"
"MIME-Version: 1.0\n"
"Content-Type: text/plain; charset=utf-8\n"
"Content-Transfer-Encoding: 8bit\n"
"Plural-Forms: nplurals=2; plural=(n > 1);\n"
"X-Poedit-Language: Portuguese\n"
"X-Poedit-Country: BRAZIL\n"

#: ../src/handler.py:209
msgid "Dump Written"
msgstr "Despejo gravado"

#: ../src/handler.py:210
msgid "The error file has been successfully written to the disk.  The program will now exit."
msgstr "O arquivo de erro foi gravado com sucesso no disco. O programa sairá agora."

#: ../src/handler.py:215
msgid "Dump Not Written"
msgstr "Despejo não gravado"

#: ../src/handler.py:216
msgid "There was a problem writing the error report."
msgstr "Houve um problema ao gravar o relatório de erro."

#: ../src/handler.py:219
msgid "No Network Available"
msgstr "Nenhuma rede disponível"

#: ../src/handler.py:220
msgid "Cannot save a bug report since there is no active network device available."
msgstr "Não é possível salvar um relatório de erro pois não há um dispositivo de rede ativo disponível."

#: ../src/savers.py:34
#, python-format
msgid ""
"Your bug could not be filed due to the following error when communicating with bugzilla:\n"
"\n"
"%s"
msgstr ""
"O seu erro não pôde ser registrado devido ao seguinte erro ao comunicar com o bugzilla:\n"
"\n"
"%s"

#: ../src/savers.py:37
#, python-format
msgid ""
"Your bug could not be filed due to bad information in the bug fields.  This is most likely an error in the bug filing program:\n"
"\n"
"%s"
msgstr ""
"O seu erro não pôde ser registrado devido a informações incorretas nos campos do relatório. É mais provável que isso seja um erro no programa de registro de erros:\n"
"\n"
"%s"

#: ../src/savers.py:41
msgid "Unable To File Bug"
msgstr "Não foi possível relatar o erro"

#: ../src/savers.py:47
msgid "Bug Filing Not Supported"
msgstr "Relato de erros não suportado"

#: ../src/savers.py:48
msgid "Your distribution does not provide a supported bug filing system, so you cannot save your exception this way."
msgstr "A sua distribuição não fornece um sistema de relato de erros suportado, portanto você não pode salvar a sua exceção desta maneira."

#: ../src/savers.py:54
msgid "Invalid Bug Information"
msgstr "Informações inválidas do erro"

#: ../src/savers.py:55
msgid "Please provide a valid username, password, and short bug description."
msgstr "Por favor, forneça um nome de usuário e senhas válidos e uma curta descrição do erro."

#: ../src/savers.py:62
msgid "Unable To Login"
msgstr "Não foi possível autenticar"

#: ../src/savers.py:63
#, python-format
msgid "There was an error logging into %s using the provided username and password."
msgstr "Houve um erro ao autenticar no %s usando o nome de usuário e senha fornecidos."

#. Tell the user we created a new bug for them and that they should
#. go add a descriptive comment.
#: ../src/savers.py:99
msgid "Bug Created"
msgstr "Relatório de erro criado"

#: ../src/savers.py:100
#, python-format
msgid ""
"A new bug has been created with your traceback attached. Please add additional information such as what you were doing when you encountered the bug, screenshots, and whatever else is appropriate to the following bug:\n"
"\n"
"%s/%s"
msgstr ""
"Um novo relatório de erro foi criado com o seu traceback anexado. Por favor, inclua quaisquer informações adicionais, como o que você estava fazendo quando encontrou o erro, capturas de tela e o que mais for apropriado para o seguinte erro:\n"
"\n"
"%s/%s"

#. Tell the user which bug they've been CC'd on and that they should
#. go add a descriptive comment.
#: ../src/savers.py:114
msgid "Bug Updated"
msgstr "Relatório de erro atualizado"

#: ../src/savers.py:115
#, python-format
msgid ""
"A bug with your information already exists.  Your account has been added to the CC list and your traceback added as a comment.  Please add additional descriptive information to the following bug:\n"
"\n"
"%s/%s"
msgstr ""
"Já existe um relatório de erro com as suas informações. A sua conta foi adicionada à lista de CC e o seu traceback adicionado como comentário. Por favor, inclua quaisquer informações descritivas adicionais para o seguinte erro:\n"
"\n"
"%s/%s"

#. Set the buttons.
#: ../src/ui/gui.py:85
msgid "_Debug"
msgstr "_Depurar"

#: ../src/ui/gui.py:87
#: ../src/ui/gui.py:152
msgid "_Exit"
msgstr "_Sair"

#: ../src/ui/gui.py:92
msgid "An unhandled exception has occurred.  This is most likely a bug.  Please save a copy of the detailed exception and file a bug report."
msgstr "Uma exceção não trata ocorreu. É mais provável que isso seja um erro. Por favor, salve uma cópia da exceção detalhada e registre um relatório de erro."

#: tmp/detailed-dialog.glade.h:1
msgid "Info"
msgstr "Info"

#: tmp/detailed-dialog.glade.h:2
msgid "_Details"
msgstr "_Detalhes"

#: tmp/exnSave.glade.h:1
msgid "Bug _description"
msgstr "_Descrição do erro"

#: tmp/exnSave.glade.h:2
msgid "Destination _file"
msgstr "_Arquivo de destino"

#: tmp/exnSave.glade.h:3
msgid ""
"Local storage\n"
"Bugzilla\n"
"Remote server (scp)"
msgstr ""
"Armazenamento local\n"
"Bugzilla\n"
"Servidor remoto (scp)"

#: tmp/exnSave.glade.h:6
msgid "Please choose a destination for saving your traceback."
msgstr "Por favor, escolha um destino para salvar o seu traceback."

#: tmp/exnSave.glade.h:7
msgid "Save"
msgstr "Salvar"

#: tmp/exnSave.glade.h:8
msgid "Select A File"
msgstr "Selecione um arquivo"

#: tmp/exnSave.glade.h:9
msgid "_Host (host:port)"
msgstr "_Máquina (máquina:porta)"

#: tmp/exnSave.glade.h:10
msgid "_Password"
msgstr "_Senha"

#: tmp/exnSave.glade.h:11
msgid "_User name"
msgstr "_Nome de usuário"

