# SOME DESCRIPTIVE TITLE.
# Copyright (C) YEAR THE PACKAGE'S COPYRIGHT HOLDER
# This file is distributed under the same license as the PACKAGE package.
# FIRST AUTHOR <EMAIL@ADDRESS>, YEAR.
#
#, fuzzy
msgid ""
msgstr ""
"Project-Id-Version: PACKAGE VERSION\n"
"Report-Msgid-Bugs-To: \n"
"POT-Creation-Date: 2009-07-16 15:00-0400\n"
"PO-Revision-Date: YEAR-MO-DA HO:MI+ZONE\n"
"Last-Translator: FULL NAME <EMAIL@ADDRESS>\n"
"Language-Team: LANGUAGE <LL@li.org>\n"
"MIME-Version: 1.0\n"
"Content-Type: text/plain; charset=CHARSET\n"
"Content-Transfer-Encoding: 8bit\n"

#: ../src/handler.py:209
msgid "Dump Written"
msgstr ""

#: ../src/handler.py:210
msgid ""
"The error file has been successfully written to the disk.  The program will "
"now exit."
msgstr ""

#: ../src/handler.py:215
msgid "Dump Not Written"
msgstr ""

#: ../src/handler.py:216
msgid "There was a problem writing the error report."
msgstr ""

#: ../src/handler.py:219
msgid "No Network Available"
msgstr ""

#: ../src/handler.py:220
msgid ""
"Cannot save a bug report since there is no active network device available."
msgstr ""

#: ../src/savers.py:34
#, python-format
msgid ""
"Your bug could not be filed due to the following error when communicating "
"with bugzilla:\n"
"\n"
"%s"
msgstr ""

#: ../src/savers.py:37
#, python-format
msgid ""
"Your bug could not be filed due to bad information in the bug fields.  This "
"is most likely an error in the bug filing program:\n"
"\n"
"%s"
msgstr ""

#: ../src/savers.py:41
msgid "Unable To File Bug"
msgstr ""

#: ../src/savers.py:47
msgid "Bug Filing Not Supported"
msgstr ""

#: ../src/savers.py:48
msgid ""
"Your distribution does not provide a supported bug filing system, so you "
"cannot save your exception this way."
msgstr ""

#: ../src/savers.py:54
msgid "Invalid Bug Information"
msgstr ""

#: ../src/savers.py:55
msgid "Please provide a valid username, password, and short bug description."
msgstr ""

#: ../src/savers.py:62
msgid "Unable To Login"
msgstr ""

#: ../src/savers.py:63
#, python-format
msgid ""
"There was an error logging into %s using the provided username and password."
msgstr ""

#. Tell the user we created a new bug for them and that they should
#. go add a descriptive comment.
#: ../src/savers.py:99
msgid "Bug Created"
msgstr ""

#: ../src/savers.py:100
#, python-format
msgid ""
"A new bug has been created with your traceback attached. Please add "
"additional information such as what you were doing when you encountered the "
"bug, screenshots, and whatever else is appropriate to the following bug:\n"
"\n"
"%s/%s"
msgstr ""

#. Tell the user which bug they've been CC'd on and that they should
#. go add a descriptive comment.
#: ../src/savers.py:114
msgid "Bug Updated"
msgstr ""

#: ../src/savers.py:115
#, python-format
msgid ""
"A bug with your information already exists.  Your account has been added to "
"the CC list and your traceback added as a comment.  Please add additional "
"descriptive information to the following bug:\n"
"\n"
"%s/%s"
msgstr ""

#. Set the buttons.
#: ../src/ui/gui.py:85
msgid "_Debug"
msgstr ""

#: ../src/ui/gui.py:87 ../src/ui/gui.py:152
msgid "_Exit"
msgstr ""

#: ../src/ui/gui.py:92
msgid ""
"An unhandled exception has occurred.  This is most likely a bug.  Please "
"save a copy of the detailed exception and file a bug report."
msgstr ""

#: tmp/detailed-dialog.glade.h:1
msgid "Info"
msgstr ""

#: tmp/detailed-dialog.glade.h:2
msgid "_Details"
msgstr ""

#: tmp/exnSave.glade.h:1
msgid "Bug _description"
msgstr ""

#: tmp/exnSave.glade.h:2
msgid "Destination _file"
msgstr ""

#: tmp/exnSave.glade.h:3
msgid ""
"Local storage\n"
"Bugzilla\n"
"Remote server (scp)"
msgstr ""

#: tmp/exnSave.glade.h:6
msgid "Please choose a destination for saving your traceback."
msgstr ""

#: tmp/exnSave.glade.h:7
msgid "Save"
msgstr ""

#: tmp/exnSave.glade.h:8
msgid "Select A File"
msgstr ""

#: tmp/exnSave.glade.h:9
msgid "_Host (host:port)"
msgstr ""

#: tmp/exnSave.glade.h:10
msgid "_Password"
msgstr ""

#: tmp/exnSave.glade.h:11
msgid "_User name"
msgstr ""
